<?xml version="1.0" encoding="utf-8"?>
<!-- This URDF was automatically created by SolidWorks to URDF Exporter! Originally created by Stephen Brawner (brawner@gmail.com) 
     Commit Version: 1.6.0-4-g7f85cfe  Build Version: 1.6.7995.38578
     For more information, please see http://wiki.ros.org/sw_urdf_exporter -->
<robot
  name="ASIMOV_FINAL">
  <link
    name="base_link">
    <inertial>
      <origin
        xyz="-0.53696 -0.21064 0.13062"
        rpy="0 0 0" />
      <mass
        value="115.58" />
      <inertia
        ixx="1.3205"
        ixy="6.2294E-05"
        ixz="0.0013085"
        iyy="0.78204"
        iyz="-3.8013E-05"
        izz="1.2135" />
    </inertial>
    <visual>
      <origin
        xyz="0 0 0"
        rpy="0 0 0" />
      <geometry>
        <mesh
          filename="package://ASIMOV_FINAL/meshes/base_link.STL" />
      </geometry>
      <material
        name="">
        <color
          rgba="0.86667 0.9098 1 1" />
      </material>
    </visual>
    <collision>
      <origin
        xyz="0 0 0"
        rpy="0 0 0" />
      <geometry>
        <mesh
          filename="package://ASIMOV_FINAL/meshes/base_link.STL" />
      </geometry>
    </collision>
  </link>
  <link
    name="FL_wheel">
    <inertial>
      <origin
        xyz="-2.28862494917048E-05 -0.0567460289699821 6.89576709134443E-05"
        rpy="0 0 0" />
      <mass
        value="0.674278629838263" />
      <inertia
        ixx="0.00142621712450202"
        ixy="-1.28841356369281E-08"
        ixz="-1.89908204592661E-07"
        iyy="0.00217017090201744"
        iyz="3.85962784206893E-08"
        izz="0.00142832090168336" />
    </inertial>
    <visual>
      <origin
        xyz="0 0 0"
        rpy="0 0 0" />
      <geometry>
        <mesh
          filename="package://ASIMOV_FINAL/meshes/FL_wheel.STL" />
      </geometry>
      <material
        name="">
        <color
          rgba="1 0.949019607843137 0.909803921568627 1" />
      </material>
    </visual>
    <collision>
      <origin
        xyz="0 0 0"
        rpy="0 0 0" />
      <geometry>
        <mesh
          filename="package://ASIMOV_FINAL/meshes/FL_wheel.STL" />
      </geometry>
    </collision>
  </link>
  <joint
    name="fl-wheel"
    type="continuous">
    <origin
      xyz="-0.057013 0.063627 -0.131"
      rpy="0 0 0" />
    <parent
      link="base_link" />
    <child
      link="FL_wheel" />
    <axis
      xyz="0 1 0" />
    <limit
      effort="10"
      velocity="10" />
    <dynamics
      damping="0.1"
      friction="0.1" />
  </joint>
  <link
    name="FR_wheel">
    <inertial>
      <origin
        xyz="7.06739163675585E-05 0.0567460290366726 1.68565957301137E-05"
        rpy="0 0 0" />
      <mass
        value="0.674278629778646" />
      <inertia
        ixx="0.00142675509369831"
        ixy="-3.95808281660765E-08"
        ixz="1.43318405792617E-07"
        iyy="0.0021701709200216"
        iyz="-9.37490473157069E-09"
        izz="0.0014277829383342" />
    </inertial>
    <visual>
      <origin
        xyz="0 0 0"
        rpy="0 0 0" />
      <geometry>
        <mesh
          filename="package://ASIMOV_FINAL/meshes/FR_wheel.STL" />
      </geometry>
      <material
        name="">
        <color
          rgba="1 0.949019607843137 0.909803921568627 1" />
      </material>
    </visual>
    <collision>
      <origin
        xyz="0 0 0"
        rpy="0 0 0" />
      <geometry>
        <mesh
          filename="package://ASIMOV_FINAL/meshes/FR_wheel.STL" />
      </geometry>
    </collision>
  </link>
  <joint
    name="fr-wheel"
    type="continuous">
    <origin
      xyz="-0.057013 -0.48363 -0.13"
      rpy="0 0 0" />
    <parent
      link="base_link" />
    <child
      link="FR_wheel" />
    <axis
      xyz="0 1 0" />
    <limit
      effort="10"
      velocity="10" />
    <dynamics
      damping="0.1"
      friction="0.1" />
  </joint>
  <link
    name="RR_wheel">
    <inertial>
      <origin
        xyz="7.0673916367725E-05 0.0567460290366725 1.68565957301137E-05"
        rpy="0 0 0" />
      <mass
        value="0.674278629778648" />
      <inertia
        ixx="0.00142675509369832"
        ixy="-3.95808281657698E-08"
        ixz="1.43318405800376E-07"
        iyy="0.00217017092002161"
        iyz="-9.3749047293493E-09"
        izz="0.0014277829383342" />
    </inertial>
    <visual>
      <origin
        xyz="0 0 0"
        rpy="0 0 0" />
      <geometry>
        <mesh
          filename="package://ASIMOV_FINAL/meshes/RR_wheel.STL" />
      </geometry>
      <material
        name="">
        <color
          rgba="1 0.949019607843137 0.909803921568627 1" />
      </material>
    </visual>
    <collision>
      <origin
        xyz="0 0 0"
        rpy="0 0 0" />
      <geometry>
        <mesh
          filename="package://ASIMOV_FINAL/meshes/RR_wheel.STL" />
      </geometry>
    </collision>
  </link>
  <joint
    name="rr-wheel"
    type="continuous">
    <origin
      xyz="-0.80601 -0.48363 -0.13"
      rpy="0 0 0" />
    <parent
      link="base_link" />
    <child
      link="RR_wheel" />
    <axis
      xyz="0 1 0" />
    <limit
      effort="10"
      velocity="10" />
    <dynamics
      damping="0.1"
      friction="0.1" />
  </joint>
  <link
    name="RL_wheel">
    <inertial>
      <origin
        xyz="-2.28862494915383E-05 -0.0567460289699819 6.89576709133055E-05"
        rpy="0 0 0" />
      <mass
        value="0.674278629838263" />
      <inertia
        ixx="0.00142621712450202"
        ixy="-1.28841356379879E-08"
        ixz="-1.89908204595834E-07"
        iyy="0.00217017090201744"
        iyz="3.85962784214815E-08"
        izz="0.00142832090168335" />
    </inertial>
    <visual>
      <origin
        xyz="0 0 0"
        rpy="0 0 0" />
      <geometry>
        <mesh
          filename="package://ASIMOV_FINAL/meshes/RL_wheel.STL" />
      </geometry>
      <material
        name="">
        <color
          rgba="1 0.949019607843137 0.909803921568627 1" />
      </material>
    </visual>
    <collision>
      <origin
        xyz="0 0 0"
        rpy="0 0 0" />
      <geometry>
        <mesh
          filename="package://ASIMOV_FINAL/meshes/RL_wheel.STL" />
      </geometry>
    </collision>
  </link>
  <joint
    name="rl-wheel"
    type="continuous">
    <origin
      xyz="-0.80601 0.063627 -0.131"
      rpy="0 0 0" />
    <parent
      link="base_link" />
    <child
      link="RL_wheel" />
    <axis
      xyz="0 1 0" />
    <limit
      effort="10"
      velocity="10" />
    <dynamics
      damping="0.1"
      friction="0.1" />
  </joint>
</robot>